----------------------------------------
Exception occurred during processing of request from ('127.0.0.1', 65487)
Traceback (most recent call last):
  File "C:\Users\EKO\AppData\Local\Programs\Python\Python311\Lib\socketserver.py", line 691, in process_request_thread
    self.finish_request(request, client_address)
  File "C:\Users\EKO\AppData\Local\Programs\Python\Python311\Lib\socketserver.py", line 361, in finish_request
    self.RequestHandlerClass(request, client_address, self)
  File "C:\Users\EKO\AppData\Local\Programs\Python\Python311\Lib\socketserver.py", line 755, in __init__
    self.handle()
  File "C:\Users\EKO\AppData\Local\Programs\Python\Python311\Lib\http\server.py", line 438, in handle
    self.handle_one_request()
  File "C:\Users\EKO\AppData\Local\Programs\Python\Python311\Lib\http\server.py", line 404, in handle_one_request
    self.raw_requestline = self.rfile.readline(65537)
                           ^^^^^^^^^^^^^^^^^^^^^^^^^^
  File "C:\Users\EKO\AppData\Local\Programs\Python\Python311\Lib\socket.py", line 706, in readinto
    return self._sock.recv_into(b)
           ^^^^^^^^^^^^^^^^^^^^^^^
ConnectionResetError: [WinError 10054] Istniej鉍e po章czenie zosta這 gwa速ownie zamkni皻e przez zdalnego hosta
----------------------------------------
----------------------------------------
Exception occurred during processing of request from ('127.0.0.1', 65488)
Traceback (most recent call last):
  File "C:\Users\EKO\AppData\Local\Programs\Python\Python311\Lib\socketserver.py", line 691, in process_request_thread
    self.finish_request(request, client_address)
  File "C:\Users\EKO\AppData\Local\Programs\Python\Python311\Lib\socketserver.py", line 361, in finish_request
    self.RequestHandlerClass(request, client_address, self)
  File "C:\Users\EKO\AppData\Local\Programs\Python\Python311\Lib\socketserver.py", line 755, in __init__
    self.handle()
  File "C:\Users\EKO\AppData\Local\Programs\Python\Python311\Lib\http\server.py", line 438, in handle
    self.handle_one_request()
  File "C:\Users\EKO\AppData\Local\Programs\Python\Python311\Lib\http\server.py", line 404, in handle_one_request
    self.raw_requestline = self.rfile.readline(65537)
                           ^^^^^^^^^^^^^^^^^^^^^^^^^^
  File "C:\Users\EKO\AppData\Local\Programs\Python\Python311\Lib\socket.py", line 706, in readinto
    return self._sock.recv_into(b)
           ^^^^^^^^^^^^^^^^^^^^^^^
ConnectionResetError: [WinError 10054] Istniej鉍e po章czenie zosta這 gwa速ownie zamkni皻e przez zdalnego hosta
----------------------------------------
----------------------------------------
Exception occurred during processing of request from ('127.0.0.1', 64753)
Traceback (most recent call last):
  File "C:\Users\EKO\AppData\Local\Programs\Python\Python311\Lib\socketserver.py", line 691, in process_request_thread
    self.finish_request(request, client_address)
  File "C:\Users\EKO\AppData\Local\Programs\Python\Python311\Lib\socketserver.py", line 361, in finish_request
    self.RequestHandlerClass(request, client_address, self)
  File "C:\Users\EKO\AppData\Local\Programs\Python\Python311\Lib\socketserver.py", line 755, in __init__
    self.handle()
  File "C:\Users\EKO\AppData\Local\Programs\Python\Python311\Lib\http\server.py", line 438, in handle
    self.handle_one_request()
  File "C:\Users\EKO\AppData\Local\Programs\Python\Python311\Lib\http\server.py", line 404, in handle_one_request
    self.raw_requestline = self.rfile.readline(65537)
                           ^^^^^^^^^^^^^^^^^^^^^^^^^^
  File "C:\Users\EKO\AppData\Local\Programs\Python\Python311\Lib\socket.py", line 706, in readinto
    return self._sock.recv_into(b)
           ^^^^^^^^^^^^^^^^^^^^^^^
ConnectionResetError: [WinError 10054] Istniej鉍e po章czenie zosta這 gwa速ownie zamkni皻e przez zdalnego hosta
----------------------------------------
