----------------------------------------
Exception occurred during processing of request from ('127.0.0.1', 53984)
Traceback (most recent call last):
  File "C:\Users\EKO\AppData\Local\Programs\Python\Python311\Lib\socketserver.py", line 691, in process_request_thread
    self.finish_request(request, client_address)
  File "C:\Users\EKO\AppData\Local\Programs\Python\Python311\Lib\socketserver.py", line 361, in finish_request
    self.RequestHandlerClass(request, client_address, self)
  File "C:\Users\EKO\AppData\Local\Programs\Python\Python311\Lib\socketserver.py", line 755, in __init__
    self.handle()
  File "C:\Users\EKO\AppData\Local\Programs\Python\Python311\Lib\http\server.py", line 438, in handle
    self.handle_one_request()
  File "C:\Users\EKO\AppData\Local\Programs\Python\Python311\Lib\http\server.py", line 404, in handle_one_request
    self.raw_requestline = self.rfile.readline(65537)
                           ^^^^^^^^^^^^^^^^^^^^^^^^^^
  File "C:\Users\EKO\AppData\Local\Programs\Python\Python311\Lib\socket.py", line 706, in readinto
    return self._sock.recv_into(b)
           ^^^^^^^^^^^^^^^^^^^^^^^
ConnectionResetError: [WinError 10054] Istniej¹ce po³¹czenie zosta³o gwa³townie zamkniête przez zdalnego hosta
----------------------------------------
----------------------------------------
Exception occurred during processing of request from ('127.0.0.1', 52481)
Traceback (most recent call last):
  File "C:\Users\EKO\AppData\Local\Programs\Python\Python311\Lib\socketserver.py", line 691, in process_request_thread
    self.finish_request(request, client_address)
  File "C:\Users\EKO\AppData\Local\Programs\Python\Python311\Lib\socketserver.py", line 361, in finish_request
    self.RequestHandlerClass(request, client_address, self)
  File "C:\Users\EKO\AppData\Local\Programs\Python\Python311\Lib\socketserver.py", line 755, in __init__
    self.handle()
  File "C:\Users\EKO\AppData\Local\Programs\Python\Python311\Lib\http\server.py", line 438, in handle
    self.handle_one_request()
  File "C:\Users\EKO\AppData\Local\Programs\Python\Python311\Lib\http\server.py", line 404, in handle_one_request
    self.raw_requestline = self.rfile.readline(65537)
                           ^^^^^^^^^^^^^^^^^^^^^^^^^^
  File "C:\Users\EKO\AppData\Local\Programs\Python\Python311\Lib\socket.py", line 706, in readinto
    return self._sock.recv_into(b)
           ^^^^^^^^^^^^^^^^^^^^^^^
ConnectionAbortedError: [WinError 10053] Nawi¹zane po³¹czenie zosta³o przerwane przez oprogramowanie zainstalowane w komputerze-hoœcie
----------------------------------------
----------------------------------------
Exception occurred during processing of request from ('127.0.0.1', 56312)
Traceback (most recent call last):
  File "C:\Users\EKO\AppData\Local\Programs\Python\Python311\Lib\socketserver.py", line 691, in process_request_thread
    self.finish_request(request, client_address)
  File "C:\Users\EKO\AppData\Local\Programs\Python\Python311\Lib\socketserver.py", line 361, in finish_request
    self.RequestHandlerClass(request, client_address, self)
  File "C:\Users\EKO\AppData\Local\Programs\Python\Python311\Lib\socketserver.py", line 755, in __init__
    self.handle()
  File "C:\Users\EKO\AppData\Local\Programs\Python\Python311\Lib\http\server.py", line 438, in handle
    self.handle_one_request()
  File "C:\Users\EKO\AppData\Local\Programs\Python\Python311\Lib\http\server.py", line 404, in handle_one_request
    self.raw_requestline = self.rfile.readline(65537)
                           ^^^^^^^^^^^^^^^^^^^^^^^^^^
  File "C:\Users\EKO\AppData\Local\Programs\Python\Python311\Lib\socket.py", line 706, in readinto
    return self._sock.recv_into(b)
           ^^^^^^^^^^^^^^^^^^^^^^^
ConnectionResetError: [WinError 10054] Istniej¹ce po³¹czenie zosta³o gwa³townie zamkniête przez zdalnego hosta
----------------------------------------
----------------------------------------
Exception occurred during processing of request from ('127.0.0.1', 56313)
Traceback (most recent call last):
  File "C:\Users\EKO\AppData\Local\Programs\Python\Python311\Lib\socketserver.py", line 691, in process_request_thread
    self.finish_request(request, client_address)
  File "C:\Users\EKO\AppData\Local\Programs\Python\Python311\Lib\socketserver.py", line 361, in finish_request
    self.RequestHandlerClass(request, client_address, self)
  File "C:\Users\EKO\AppData\Local\Programs\Python\Python311\Lib\socketserver.py", line 755, in __init__
    self.handle()
  File "C:\Users\EKO\AppData\Local\Programs\Python\Python311\Lib\http\server.py", line 438, in handle
    self.handle_one_request()
  File "C:\Users\EKO\AppData\Local\Programs\Python\Python311\Lib\http\server.py", line 404, in handle_one_request
    self.raw_requestline = self.rfile.readline(65537)
                           ^^^^^^^^^^^^^^^^^^^^^^^^^^
  File "C:\Users\EKO\AppData\Local\Programs\Python\Python311\Lib\socket.py", line 706, in readinto
    return self._sock.recv_into(b)
           ^^^^^^^^^^^^^^^^^^^^^^^
ConnectionResetError: [WinError 10054] Istniej¹ce po³¹czenie zosta³o gwa³townie zamkniête przez zdalnego hosta
----------------------------------------
----------------------------------------
Exception occurred during processing of request from ('127.0.0.1', 52077)
Traceback (most recent call last):
  File "C:\Users\EKO\AppData\Local\Programs\Python\Python311\Lib\socketserver.py", line 691, in process_request_thread
    self.finish_request(request, client_address)
  File "C:\Users\EKO\AppData\Local\Programs\Python\Python311\Lib\socketserver.py", line 361, in finish_request
    self.RequestHandlerClass(request, client_address, self)
  File "C:\Users\EKO\AppData\Local\Programs\Python\Python311\Lib\socketserver.py", line 755, in __init__
    self.handle()
  File "C:\Users\EKO\AppData\Local\Programs\Python\Python311\Lib\http\server.py", line 438, in handle
    self.handle_one_request()
  File "C:\Users\EKO\AppData\Local\Programs\Python\Python311\Lib\http\server.py", line 404, in handle_one_request
    self.raw_requestline = self.rfile.readline(65537)
                           ^^^^^^^^^^^^^^^^^^^^^^^^^^
  File "C:\Users\EKO\AppData\Local\Programs\Python\Python311\Lib\socket.py", line 706, in readinto
    return self._sock.recv_into(b)
           ^^^^^^^^^^^^^^^^^^^^^^^
ConnectionAbortedError: [WinError 10053] Nawi¹zane po³¹czenie zosta³o przerwane przez oprogramowanie zainstalowane w komputerze-hoœcie
----------------------------------------
----------------------------------------
Exception occurred during processing of request from ('127.0.0.1', 63247)
----------------------------------------
Exception occurred during processing of request from ('127.0.0.1', 51196)
Traceback (most recent call last):
  File "C:\Users\EKO\AppData\Local\Programs\Python\Python311\Lib\socketserver.py", line 691, in process_request_thread
    self.finish_request(request, client_address)
  File "C:\Users\EKO\AppData\Local\Programs\Python\Python311\Lib\socketserver.py", line 361, in finish_request
    self.RequestHandlerClass(request, client_address, self)
  File "C:\Users\EKO\AppData\Local\Programs\Python\Python311\Lib\socketserver.py", line 755, in __init__
    self.handle()
  File "C:\Users\EKO\AppData\Local\Programs\Python\Python311\Lib\http\server.py", line 438, in handle
    self.handle_one_request()
  File "C:\Users\EKO\AppData\Local\Programs\Python\Python311\Lib\http\server.py", line 404, in handle_one_request
    self.raw_requestline = self.rfile.readline(65537)
                           ^^^^^^^^^^^^^^^^^^^^^^^^^^
  File "C:\Users\EKO\AppData\Local\Programs\Python\Python311\Lib\socket.py", line 706, in readinto
    return self._sock.recv_into(b)
           ^^^^^^^^^^^^^^^^^^^^^^^
ConnectionAbortedError: [WinError 10053] Nawi¹zane po³¹czenie zosta³o przerwane przez oprogramowanie zainstalowane w komputerze-hoœcie
----------------------------------------
Traceback (most recent call last):
  File "C:\Users\EKO\AppData\Local\Programs\Python\Python311\Lib\socketserver.py", line 691, in process_request_thread
    self.finish_request(request, client_address)
  File "C:\Users\EKO\AppData\Local\Programs\Python\Python311\Lib\socketserver.py", line 361, in finish_request
    self.RequestHandlerClass(request, client_address, self)
  File "C:\Users\EKO\AppData\Local\Programs\Python\Python311\Lib\socketserver.py", line 755, in __init__
    self.handle()
  File "C:\Users\EKO\AppData\Local\Programs\Python\Python311\Lib\http\server.py", line 438, in handle
    self.handle_one_request()
  File "C:\Users\EKO\AppData\Local\Programs\Python\Python311\Lib\http\server.py", line 404, in handle_one_request
    self.raw_requestline = self.rfile.readline(65537)
                           ^^^^^^^^^^^^^^^^^^^^^^^^^^
  File "C:\Users\EKO\AppData\Local\Programs\Python\Python311\Lib\socket.py", line 706, in readinto
    return self._sock.recv_into(b)
           ^^^^^^^^^^^^^^^^^^^^^^^
ConnectionAbortedError: [WinError 10053] Nawi¹zane po³¹czenie zosta³o przerwane przez oprogramowanie zainstalowane w komputerze-hoœcie
----------------------------------------
----------------------------------------
Exception occurred during processing of request from ('127.0.0.1', 59885)
Traceback (most recent call last):
  File "C:\Users\EKO\AppData\Local\Programs\Python\Python311\Lib\socketserver.py", line 691, in process_request_thread
    self.finish_request(request, client_address)
  File "C:\Users\EKO\AppData\Local\Programs\Python\Python311\Lib\socketserver.py", line 361, in finish_request
    self.RequestHandlerClass(request, client_address, self)
  File "C:\Users\EKO\AppData\Local\Programs\Python\Python311\Lib\socketserver.py", line 755, in __init__
    self.handle()
  File "C:\Users\EKO\AppData\Local\Programs\Python\Python311\Lib\http\server.py", line 438, in handle
    self.handle_one_request()
  File "C:\Users\EKO\AppData\Local\Programs\Python\Python311\Lib\http\server.py", line 404, in handle_one_request
    self.raw_requestline = self.rfile.readline(65537)
                           ^^^^^^^^^^^^^^^^^^^^^^^^^^
  File "C:\Users\EKO\AppData\Local\Programs\Python\Python311\Lib\socket.py", line 706, in readinto
    return self._sock.recv_into(b)
           ^^^^^^^^^^^^^^^^^^^^^^^
ConnectionAbortedError: [WinError 10053] Nawi¹zane po³¹czenie zosta³o przerwane przez oprogramowanie zainstalowane w komputerze-hoœcie
----------------------------------------
----------------------------------------
Exception occurred during processing of request from ('127.0.0.1', 59000)
Traceback (most recent call last):
  File "C:\Users\EKO\AppData\Local\Programs\Python\Python311\Lib\socketserver.py", line 691, in process_request_thread
    self.finish_request(request, client_address)
  File "C:\Users\EKO\AppData\Local\Programs\Python\Python311\Lib\socketserver.py", line 361, in finish_request
    self.RequestHandlerClass(request, client_address, self)
  File "C:\Users\EKO\AppData\Local\Programs\Python\Python311\Lib\socketserver.py", line 755, in __init__
    self.handle()
  File "C:\Users\EKO\AppData\Local\Programs\Python\Python311\Lib\http\server.py", line 438, in handle
    self.handle_one_request()
  File "C:\Users\EKO\AppData\Local\Programs\Python\Python311\Lib\http\server.py", line 404, in handle_one_request
    self.raw_requestline = self.rfile.readline(65537)
                           ^^^^^^^^^^^^^^^^^^^^^^^^^^
  File "C:\Users\EKO\AppData\Local\Programs\Python\Python311\Lib\socket.py", line 706, in readinto
    return self._sock.recv_into(b)
           ^^^^^^^^^^^^^^^^^^^^^^^
ConnectionAbortedError: [WinError 10053] Nawi¹zane po³¹czenie zosta³o przerwane przez oprogramowanie zainstalowane w komputerze-hoœcie
----------------------------------------
----------------------------------------
Exception occurred during processing of request from ('127.0.0.1', 57483)
Traceback (most recent call last):
  File "C:\Users\EKO\AppData\Local\Programs\Python\Python311\Lib\socketserver.py", line 691, in process_request_thread
    self.finish_request(request, client_address)
  File "C:\Users\EKO\AppData\Local\Programs\Python\Python311\Lib\socketserver.py", line 361, in finish_request
    self.RequestHandlerClass(request, client_address, self)
  File "C:\Users\EKO\AppData\Local\Programs\Python\Python311\Lib\socketserver.py", line 755, in __init__
    self.handle()
  File "C:\Users\EKO\AppData\Local\Programs\Python\Python311\Lib\http\server.py", line 438, in handle
    self.handle_one_request()
  File "C:\Users\EKO\AppData\Local\Programs\Python\Python311\Lib\http\server.py", line 404, in handle_one_request
    self.raw_requestline = self.rfile.readline(65537)
                           ^^^^^^^^^^^^^^^^^^^^^^^^^^
  File "C:\Users\EKO\AppData\Local\Programs\Python\Python311\Lib\socket.py", line 706, in readinto
    return self._sock.recv_into(b)
           ^^^^^^^^^^^^^^^^^^^^^^^
ConnectionAbortedError: [WinError 10053] Nawi¹zane po³¹czenie zosta³o przerwane przez oprogramowanie zainstalowane w komputerze-hoœcie
----------------------------------------
----------------------------------------
Exception occurred during processing of request from ('127.0.0.1', 53407)
Traceback (most recent call last):
  File "C:\Users\EKO\AppData\Local\Programs\Python\Python311\Lib\socketserver.py", line 691, in process_request_thread
    self.finish_request(request, client_address)
  File "C:\Users\EKO\AppData\Local\Programs\Python\Python311\Lib\socketserver.py", line 361, in finish_request
    self.RequestHandlerClass(request, client_address, self)
  File "C:\Users\EKO\AppData\Local\Programs\Python\Python311\Lib\socketserver.py", line 755, in __init__
    self.handle()
  File "C:\Users\EKO\AppData\Local\Programs\Python\Python311\Lib\http\server.py", line 438, in handle
    self.handle_one_request()
  File "C:\Users\EKO\AppData\Local\Programs\Python\Python311\Lib\http\server.py", line 404, in handle_one_request
    self.raw_requestline = self.rfile.readline(65537)
                           ^^^^^^^^^^^^^^^^^^^^^^^^^^
  File "C:\Users\EKO\AppData\Local\Programs\Python\Python311\Lib\socket.py", line 706, in readinto
    return self._sock.recv_into(b)
           ^^^^^^^^^^^^^^^^^^^^^^^
ConnectionAbortedError: [WinError 10053] Nawi¹zane po³¹czenie zosta³o przerwane przez oprogramowanie zainstalowane w komputerze-hoœcie
----------------------------------------
----------------------------------------
Exception occurred during processing of request from ('127.0.0.1', 50197)
Traceback (most recent call last):
  File "C:\Users\EKO\AppData\Local\Programs\Python\Python311\Lib\socketserver.py", line 691, in process_request_thread
    self.finish_request(request, client_address)
  File "C:\Users\EKO\AppData\Local\Programs\Python\Python311\Lib\socketserver.py", line 361, in finish_request
    self.RequestHandlerClass(request, client_address, self)
  File "C:\Users\EKO\AppData\Local\Programs\Python\Python311\Lib\socketserver.py", line 755, in __init__
    self.handle()
  File "C:\Users\EKO\AppData\Local\Programs\Python\Python311\Lib\http\server.py", line 438, in handle
    self.handle_one_request()
  File "C:\Users\EKO\AppData\Local\Programs\Python\Python311\Lib\http\server.py", line 404, in handle_one_request
    self.raw_requestline = self.rfile.readline(65537)
                           ^^^^^^^^^^^^^^^^^^^^^^^^^^
  File "C:\Users\EKO\AppData\Local\Programs\Python\Python311\Lib\socket.py", line 706, in readinto
    return self._sock.recv_into(b)
           ^^^^^^^^^^^^^^^^^^^^^^^
ConnectionAbortedError: [WinError 10053] Nawi¹zane po³¹czenie zosta³o przerwane przez oprogramowanie zainstalowane w komputerze-hoœcie
----------------------------------------
